<?xml version="1.0" encoding="UTF-8"?>

<robot name="barista_robot">

    <!-- LINKS  -->

    <!-- parent -->
    <link name="base_footprint">
    </link>

    <!-- base -->
    <link name="base_link">
        <visual>
            <origin xyz="0 0 0" rpy="0 0 0" />
            <geometry>
                <!-- units in meters -->
                <cylinder length="0.155" radius="0.178" />
            </geometry>
            <material name="blue">
                <color rgba="0 0 1 0.5" />
            </material>
        </visual>
        <collision>
            <origin xyz="0 0 0" rpy="0 0 0" />
            <geometry>
                <!-- units in meters -->
                <cylinder length="0.155" radius="0.178" />
            </geometry>
        </collision>
        <inertial>
            <origin xyz="0 0 0" rpy="0 0 0" />
            <!-- units in kilograms -->
            <mass value="10" />
            <!-- inertial tensors for solid cylinder -->
            <inertia
                ixx="0.09923" ixy="0.0" ixz="0.0"
                iyy="0.09923" iyz="0.0"
                izz="0.15842"
            />
        </inertial>
    </link>

    <!-- right wheel -->
    <link name="right_wheel">
        <visual>
            <origin xyz="0 0 0" rpy="1.5707 0 0" />
            <geometry>
                <!-- units in meters -->
                <cylinder length="0.0206" radius="0.0352" />
            </geometry>
            <material name="red">
                <color rgba="1 0 0 1" />
            </material>
        </visual>
        <collision>
            <origin xyz="0 0 0" rpy="1.5707 0 0" />
            <geometry>
                <!-- units in meters -->
                <cylinder length="0.0206" radius="0.0352" />
            </geometry>
        </collision>
        <inertial>
            <origin xyz="0 0 0" rpy="0 0 0" />
            <!-- units in kilograms -->
            <mass value="1" />
            <!-- inertial tensors for solid cylinder -->
            <inertia
                ixx="0.0003451" ixy="0.0" ixz="0.0"
                iyy="0.0003451" iyz="0.0"
                izz="0.0006195"
            />
        </inertial>
    </link>

    <!-- left wheel -->
    <link name="left_wheel">
        <visual>
            <origin xyz="0 0 0" rpy="1.5707 0 0" />
            <geometry>
                <!-- units in meters -->
                <cylinder length="0.0206" radius="0.0352" />
            </geometry>
            <material name="red">
                <color rgba="1 0 0 1" />
            </material>
        </visual>
        <collision>
            <origin xyz="0 0 0" rpy="1.5707 0 0" />
            <geometry>
                <!-- units in meters -->
                <cylinder length="0.0206" radius="0.0352" />
            </geometry>
        </collision>
        <inertial>
            <origin xyz="0 0 0" rpy="0 0 0" />
            <!-- units in kilograms -->
            <mass value="1" />
            <!-- inertial tensors for solid cylinder -->
            <inertia
                ixx="0.0003451" ixy="0.0" ixz="0.0"
                iyy="0.0003451" iyz="0.0"
                izz="0.0006195"
            />
        </inertial>
    </link>

    <!-- front caster -->
    <link name="front_caster">
        <visual>
            <origin xyz="0 0 0" rpy="0 0 0" />
            <geometry>
                <!-- units in meters -->
                <sphere radius="0.0352" />
            </geometry>
            <material name="white">
                <color rgba="1 1 1 1" />
            </material>
        </visual>
        <collision>
            <origin xyz="0 0 0" rpy="0 0 0" />
            <geometry>
                <!-- units in meters -->
                <sphere radius="0.0352" />
            </geometry>
        </collision>
        <inertial>
            <origin xyz="0 0 0" rpy="0 0 0" />
            <!-- units in kilograms -->
            <mass value="1" />
            <!-- inertial tensors for solid sphere -->
            <inertia
                ixx="0.000826" ixy="0.0" ixz="0.0"
                iyy="0.000826" iyz="0.0"
                izz="0.000826"
            />
        </inertial>
    </link>

    <!-- back caster -->
    <link name="back_caster">
        <visual>
            <origin xyz="0 0 0" rpy="0 0 0" />
            <geometry>
                <!-- units in meters -->
                <sphere radius="0.0352" />
            </geometry>
            <material name="white">
                <color rgba="1 1 1 1" />
            </material>
        </visual>
        <collision>
            <origin xyz="0 0 0" rpy="0 0 0" />
            <geometry>
                <!-- units in meters -->
                <sphere radius="0.0352" />
            </geometry>
        </collision>
        <inertial>
            <origin xyz="0 0 0" rpy="0 0 0" />
            <!-- units in kilograms -->
            <mass value="1" />
            <!-- inertial tensors for solid sphere -->
            <inertia
                ixx="0.000826" ixy="0.0" ixz="0.0"
                iyy="0.000826" iyz="0.0"
                izz="0.000826"
            />
        </inertial>
    </link>

    <!-- front right standoff -->
    <link name="fr_standoff">
        <visual>
            <origin xyz="0 0 0" rpy="0 0 0" />
            <geometry>
                <!-- units in meters -->
                <cylinder length="0.220" radius="0.010" />
            </geometry>
            <material name="white">
                <color rgba="1 1 1 0.5" />
            </material>
        </visual>
        <collision>
            <origin xyz="0 0 0" rpy="0 0 0" />
            <geometry>
                <!-- units in meters -->
                <cylinder length="0.220" radius="0.010" />
            </geometry>
        </collision>
        <inertial>
            <origin xyz="0 0 0" rpy="0 0 0" />
            <!-- units in kilograms -->
            <mass value="1" />
            <!-- inertial tensors for solid cylinder -->
            <inertia
                ixx="0.004058" ixy="0.0" ixz="0.0"
                iyy="0.004058" iyz="0.0"
                izz="0.00005"
            />
        </inertial>
    </link>

    <!-- front left standoff -->
    <link name="fl_standoff">
        <visual>
            <origin xyz="0 0 0" rpy="0 0 0" />
            <geometry>
                <!-- units in meters -->
                <cylinder length="0.220" radius="0.010" />
            </geometry>
            <material name="white">
                <color rgba="1 1 1 0.5" />
            </material>
        </visual>
        <collision>
            <origin xyz="0 0 0" rpy="0 0 0" />
            <geometry>
                <!-- units in meters -->
                <cylinder length="0.220" radius="0.010" />
            </geometry>
        </collision>
        <inertial>
            <origin xyz="0 0 0" rpy="0 0 0" />
            <!-- units in kilograms -->
            <mass value="1" />
            <!-- inertial tensors for solid cylinder -->
            <inertia
                ixx="0.004058" ixy="0.0" ixz="0.0"
                iyy="0.004058" iyz="0.0"
                izz="0.00005"
            />
        </inertial>
    </link>

    <!-- back right standoff -->
    <link name="br_standoff">
        <visual>
            <origin xyz="0 0 0" rpy="0 0 0" />
            <geometry>
                <!-- units in meters -->
                <cylinder length="0.220" radius="0.010" />
            </geometry>
            <material name="white">
                <color rgba="1 1 1 0.5" />
            </material>
        </visual>
        <collision>
            <origin xyz="0 0 0" rpy="0 0 0" />
            <geometry>
                <!-- units in meters -->
                <cylinder length="0.220" radius="0.010" />
            </geometry>
        </collision>
        <inertial>
            <origin xyz="0 0 0" rpy="0 0 0" />
            <!-- units in kilograms -->
            <mass value="1" />
            <!-- inertial tensors for solid cylinder -->
            <inertia
                ixx="0.004058" ixy="0.0" ixz="0.0"
                iyy="0.004058" iyz="0.0"
                izz="0.00005"
            />
        </inertial>
    </link>

    <!-- back left standoff -->
    <link name="bl_standoff">
        <visual>
            <origin xyz="0 0 0" rpy="0 0 0" />
            <geometry>
                <!-- units in meters -->
                <cylinder length="0.220" radius="0.010" />
            </geometry>
            <material name="white">
                <color rgba="1 1 1 0.5" />
            </material>
        </visual>
        <collision>
            <origin xyz="0 0 0" rpy="0 0 0" />
            <geometry>
                <!-- units in meters -->
                <cylinder length="0.220" radius="0.010" />
            </geometry>
        </collision>
        <inertial>
            <origin xyz="0 0 0" rpy="0 0 0" />
            <!-- units in kilograms -->
            <mass value="1" />
            <!-- inertial tensors for solid cylinder -->
            <inertia
                ixx="0.004058" ixy="0.0" ixz="0.0"
                iyy="0.004058" iyz="0.0"
                izz="0.00005"
            />
        </inertial>
    </link>

    <!-- cup holder -->
    <link name="cup_holder">
        <visual>
            <origin xyz="0 0 0" rpy="0 0 0" />
            <geometry>
                <!-- units in meters -->
                <cylinder length="0.090" radius="0.160" />
            </geometry>
            <material name="blue">
                <color rgba="0 0 1 0.5" />
            </material>
        </visual>
        <collision>
            <origin xyz="0 0 0" rpy="0 0 0" />
            <geometry>
                <!-- units in meters -->
                <cylinder length="0.090" radius="0.160" />
            </geometry>
        </collision>
        <inertial>
            <origin xyz="0 0 0" rpy="0 0 0" />
            <!-- units in kilograms -->
            <mass value="7" />
            <!-- inertial tensors for solid cylinder -->
            <inertia
                ixx="0.049525" ixy="0.0" ixz="0.0"
                iyy="0.049525" iyz="0.0"
                izz="0.0896"
            />
        </inertial>
    </link>

    <!-- base laser -->
    <link name="base_laser">
        <visual>
            <origin xyz="0 0 0" rpy="0 0 0" />
            <geometry>
                <!-- units in meters -->
                <!-- assumed solid cylinder as geometry for the sensor -->
                <mesh filename="package://barista_robot_description/meshes/hokuyo_urg_04lx.dae" />
            </geometry>
            <material name="yellow">
                <color rgba="1 1 0 1" />
            </material>
        </visual>
        <collision>
            <origin xyz="0 0 0" rpy="0 0 0" />
            <geometry>
                <!-- units in meters -->
                <cylinder length="0.022" radius="0.022" />
            </geometry>
        </collision>
        <inertial>
            <origin xyz="0 0 0" rpy="0 0 0" />
            <!-- units in kilograms -->
            <!-- assumed negligible mass for the sensor -->
            <mass value="0.001" />
            <!-- inertial tensors for solid cylinder -->
            <inertia
                ixx="0.00000016133" ixy="0.0" ixz="0.0"
                iyy="0.00000016133" iyz="0.0"
                izz="0.000000242"
            />
        </inertial>
    </link>

    <!-- JOINTS -->

    <!-- base_footprint to base_link joint -->
    <joint name="joint_parent_to_base" type="fixed">
        <parent link="base_footprint" />
        <child link="base_link" />
        <origin xyz="0 0 0.0775" rpy="0 0 0" />
    </joint>

    <!-- base_link to right_wheel joint -->
    <joint name="joint_base_to_right_wheel" type="continuous">
        <parent link="base_link" />
        <child link="right_wheel" />
        <origin xyz="0 -0.15 -0.0775" rpy="0 0 0" />
        <axis xyz="0 1 0" />
    </joint>

    <!-- base_link to left_wheel joint -->
    <joint name="joint_base_to_left_wheel" type="continuous">
        <parent link="base_link" />
        <child link="left_wheel" />
        <origin xyz="0 0.15 -0.0775" rpy="0 0 0" />
        <axis xyz="0 1 0" />
    </joint>

    <!-- base_link to front_caster joint -->
    <joint name="joint_base_to_front_caster" type="fixed">
        <parent link="base_link" />
        <child link="front_caster" />
        <origin xyz="0.12 0 -0.0775" rpy="0 0 0" />
    </joint>

    <!-- base_link to back_caster joint -->
    <joint name="joint_base_to_back_caster" type="fixed">
        <parent link="base_link" />
        <child link="back_caster" />
        <origin xyz="-0.12 0 -0.0775" rpy="0 0 0" />
    </joint>

    <!-- base_link to fr_standoff joint -->
    <joint name="joint_base_to_fr_standoff" type="fixed">
        <parent link="base_link" />
        <child link="fr_standoff" />
        <origin xyz="0.04 -0.12 0.1875" rpy="0 0 0" />
    </joint>

    <!-- base_link to fl_standoff joint -->
    <joint name="joint_base_to_fl_standoff" type="fixed">
        <parent link="base_link" />
        <child link="fl_standoff" />
        <origin xyz="0.04 0.12 0.1875" rpy="0 0 0" />
    </joint>

    <!-- base_link to br_standoff joint -->
    <joint name="joint_base_to_br_standoff" type="fixed">
        <parent link="base_link" />
        <child link="br_standoff" />
        <origin xyz="-0.04 -0.12 0.1875" rpy="0 0 0" />
    </joint>

    <!-- base_link to bl_standoff joint -->
    <joint name="joint_base_to_bl_standoff" type="fixed">
        <parent link="base_link" />
        <child link="bl_standoff" />
        <origin xyz="-0.04 0.12 0.1875" rpy="0 0 0" />
    </joint>

    <!-- fr_standoff to cup_holder joint -->
    <joint name="joint_fr_standoff_to_cup_holder" type="fixed">
        <parent link="fr_standoff" />
        <child link="cup_holder" />
        <origin xyz="-0.04 0.12 0.155" rpy="0 0 0" />
    </joint>

    <!-- base_link to base_laser joint -->
    <joint name="joint_base_to_base_laser" type="fixed">
        <parent link="base_link" />
        <child link="base_laser" />
        <origin xyz="0 0 0.0885" rpy="0 0 0" />
    </joint>

    <!-- GAZEBO -->

    <!-- properties for base_link -->
    <gazebo reference="base_link">
        <material>Gazebo/Blue </material>
    </gazebo>

    <!-- properties for right_wheel -->
    <gazebo reference="right_wheel">
        <mu1>1</mu1>
        <mu2>1</mu2>
        <material>Gazebo/Red </material>
    </gazebo>

    <!-- properties for left_wheel -->
    <gazebo reference="left_wheel">
        <mu1>1</mu1>
        <mu2>1</mu2>
        <material>Gazebo/Red </material>
    </gazebo>

    <!-- properties for front_caster -->
    <gazebo reference="front_caster">
        <preserveFixedJoint>true</preserveFixedJoint>
        <mu1>0</mu1>
        <mu2>0</mu2>
        <material>Gazebo/White </material>
    </gazebo>

    <!-- properties for back_caster -->
    <gazebo reference="back_caster">
        <preserveFixedJoint>true</preserveFixedJoint>
        <mu1>0</mu1>
        <mu2>0</mu2>
        <material>Gazebo/White </material>
    </gazebo>

    <!-- properties for fr_standoff -->
    <gazebo reference="fr_standoff">
        <material>Gazebo/White </material>
    </gazebo>

    <!-- properties for fl_standoff -->
    <gazebo reference="fl_standoff">
        <material>Gazebo/White </material>
    </gazebo>

    <!-- properties for br_standoff -->
    <gazebo reference="br_standoff">
        <material>Gazebo/White </material>
    </gazebo>

    <!-- properties for bl_standoff -->
    <gazebo reference="bl_standoff">
        <material>Gazebo/White </material>
    </gazebo>

    <!-- properties for cup_holder -->
    <gazebo reference="cup_holder">
        <material>Gazebo/Blue </material>
    </gazebo>

    <!-- properties for base_laser -->
    <gazebo reference="base_laser">
        <material>Gazebo/Yellow </material>
    </gazebo>

    <!-- plugin for robot control -->
    <gazebo>
        <plugin filename="libgazebo_ros_diff_drive.so" name="differential_drive_controller">
            <!-- defined parameters -->
            <left_joint>joint_base_to_right_wheel</left_joint>
            <right_joint>joint_base_to_left_wheel</right_joint>
            <wheel_separation>0.30</wheel_separation>
            <wheel_diameter>0.0704</wheel_diameter>
            <!-- default parameters -->
            <max_wheel_torque>1.0</max_wheel_torque>
            <max_wheel_acceleration>2.0</max_wheel_acceleration>
            <publish_odom>true</publish_odom>
            <publish_odom_tf>true</publish_odom_tf>
            <odometry_frame>odom</odometry_frame>
            <robot_base_frame>base_footprint</robot_base_frame>
            <ros>
                <argument>/cmd_vel:=/cmd_vel</argument>
                <argument>/odom:=/odom</argument>
            </ros>
        </plugin>
    </gazebo>

    <!-- plugin for laser sensor -->
    <gazebo reference="base_laser">
        <sensor type="ray" name="head_hokuyo_sensor">
            <pose>0 0 0 0 0 0</pose>
            <ray>
                <scan>
                    <horizontal>
                        <samples>720</samples>
                        <resolution>1.0</resolution>
                        <min_angle>-3.14</min_angle>
                        <max_angle>3.14</max_angle>
                    </horizontal>
                </scan>
                <range>
                    <min>0.10</min>
                    <max>7.0</max>
                    <resolution>0.01</resolution>
                </range>
                <noise>
                    <type>gaussian</type>
                    <mean>0.0</mean>
                    <stddev>0.01</stddev>
                </noise>
            </ray>
            <always_on>true</always_on>
            <visualize>true</visualize>
            <update_rate>100.0</update_rate>
            <plugin name="laser" filename="libgazebo_ros_ray_sensor.so">
                <ros>
                    <remapping>~/out:=scan</remapping>
                </ros>
                <output_type>sensor_msgs/LaserScan</output_type>
            </plugin>
        </sensor>
    </gazebo>

    <!-- plugin for joint state publisher -->
    <gazebo>
        <plugin name="barista_robot_joint_state" filename="libgazebo_ros_joint_state_publisher.so">
            <update_rate>30</update_rate>
            <joint_name>joint_base_to_right_wheel</joint_name>
            <joint_name>joint_base_to_left_wheel</joint_name>
        </plugin>
    </gazebo>

</robot>